<?xml version="1.0"?>
<robot name="humanoid_biped">

  <link name="torso">
    <inertial>
      <mass value="10"/>
      <origin xyz="0 0 0" rpy="0 0 0"/>
      <inertia ixx="0.1" ixy="0" ixz="0" iyy="0.1" iyz="0" izz="0.1"/>
    </inertial>
    <visual>
      <origin xyz="0 0 0" rpy="0 0 0"/>
      <geometry><box size="0.1 0.05 0.4"/></geometry>
      <material name="blue"><color rgba="0 0 1 1"/></material>
    </visual>
    <collision>
       <origin xyz="0 0 0" rpy="0 0 0"/>
      <geometry><box size="0.1 0.05 0.4"/></geometry>
    </collision>
  </link>

  <link name="head">
    <inertial>
      <mass value="2"/>
      <origin xyz="0 0 0" rpy="0 0 0"/>
      <inertia ixx="0.02" ixy="0" ixz="0" iyy="0.02" iyz="0" izz="0.02"/>
    </inertial>
    <visual>
       <origin xyz="0 0 0" rpy="0 0 0"/>
      <geometry><sphere radius="0.08"/></geometry>
      <material name="skin"><color rgba="1 0.8 0.6 1"/></material>
    </visual>
    <collision>
       <origin xyz="0 0 0" rpy="0 0 0"/>
       <geometry><sphere radius="0.08"/></geometry>
    </collision>
  </link>
  <joint name="j_head" type="revolute"> <parent link="torso"/>
    <child link="head"/>
    <origin xyz="0 0 0.2" rpy="0 0 0"/> <axis xyz="0 1 0"/>
    <limit lower="-0.785" upper="0.785" effort="10" velocity="5"/> </joint>

  <link name="upperarm_l">
    <inertial>
      <mass value="2"/>
      <origin xyz="0 0 -0.06" rpy="0 0 0"/> <inertia ixx="0.005" ixy="0" ixz="0" iyy="0.005" iyz="0" izz="0.001"/>
    </inertial>
    <visual>
      <origin xyz="0 0 -0.06" rpy="0 0 0"/>
      <geometry><box size="0.04 0.04 0.12"/></geometry> <material name="orange"><color rgba="1 0.5 0 1"/></material>
    </visual>
    <collision>
      <origin xyz="0 0 -0.06" rpy="0 0 0"/>
      <geometry><box size="0.04 0.04 0.12"/></geometry>
    </collision>
  </link>
  <joint name="j_shoulder_l" type="revolute"> <parent link="torso"/>
    <child link="upperarm_l"/>
    <origin xyz="0.07 0 0.18" rpy="0 0 0"/> <axis xyz="0 1 0"/>
    <limit lower="-1.57" upper="1.57" effort="50" velocity="10"/>
  </joint>

  <link name="forearm_l">
     <inertial>
      <mass value="1.5"/>
       <origin xyz="0 0 -0.06" rpy="0 0 0"/> <inertia ixx="0.004" ixy="0" ixz="0" iyy="0.004" iyz="0" izz="0.001"/>
    </inertial>
    <visual>
       <origin xyz="0 0 -0.06" rpy="0 0 0"/>
      <geometry><box size="0.035 0.035 0.12"/></geometry>
      <material name="lightorange"><color rgba="1 0.7 0.3 1"/></material>
    </visual>
    <collision>
       <origin xyz="0 0 -0.06" rpy="0 0 0"/>
      <geometry><box size="0.035 0.035 0.12"/></geometry>
    </collision>
  </link>
  <joint name="j_elbow_l" type="revolute"> <parent link="upperarm_l"/>
     <child link="forearm_l"/>
    <origin xyz="0 0 -0.12" rpy="0 0 0"/> <axis xyz="0 1 0"/>
    <limit lower="0" upper="2.618" effort="30" velocity="10"/> </joint>

  <link name="upperarm_r">
    <inertial>
      <mass value="2"/>
      <origin xyz="0 0 -0.06" rpy="0 0 0"/>
      <inertia ixx="0.005" ixy="0" ixz="0" iyy="0.005" iyz="0" izz="0.001"/>
    </inertial>
    <visual>
      <origin xyz="0 0 -0.06" rpy="0 0 0"/>
      <geometry><box size="0.04 0.04 0.12"/></geometry>
      <material name="orange"/>
    </visual>
    <collision>
      <origin xyz="0 0 -0.06" rpy="0 0 0"/>
      <geometry><box size="0.04 0.04 0.12"/></geometry>
    </collision>
  </link>
  <joint name="j_shoulder_r" type="revolute"> <parent link="torso"/>
    <child link="upperarm_r"/>
    <origin xyz="-0.07 0 0.18" rpy="0 0 0"/>
    <axis xyz="0 1 0"/>
    <limit lower="-1.57" upper="1.57" effort="50" velocity="10"/>
  </joint>

  <link name="forearm_r">
     <inertial>
      <mass value="1.5"/>
       <origin xyz="0 0 -0.06" rpy="0 0 0"/>
      <inertia ixx="0.004" ixy="0" ixz="0" iyy="0.004" iyz="0" izz="0.001"/>
    </inertial>
    <visual>
       <origin xyz="0 0 -0.06" rpy="0 0 0"/>
      <geometry><box size="0.035 0.035 0.12"/></geometry>
       <material name="lightorange"/>
    </visual>
    <collision>
       <origin xyz="0 0 -0.06" rpy="0 0 0"/>
      <geometry><box size="0.035 0.035 0.12"/></geometry>
    </collision>
  </link>
  <joint name="j_elbow_r" type="revolute"> <parent link="upperarm_r"/>
    <child link="forearm_r"/>
     <origin xyz="0 0 -0.12" rpy="0 0 0"/>
    <axis xyz="0 1 0"/>
    <limit lower="0" upper="2.618" effort="30" velocity="10"/>
  </joint>

  <link name="thigh_l">
    <inertial>
      <mass value="5"/>
      <origin xyz="0 0 -0.15" rpy="0 0 0"/> <inertia ixx="0.05" ixy="0" ixz="0" iyy="0.05" iyz="0" izz="0.01"/>
    </inertial>
    <visual>
      <origin xyz="0 0 -0.15" rpy="0 0 0"/>
      <geometry><box size="0.08 0.05 0.3"/></geometry>
      <material name="red"><color rgba="1 0 0 1"/></material>
    </visual>
    <collision>
      <origin xyz="0 0 -0.15" rpy="0 0 0"/>
      <geometry><box size="0.08 0.05 0.3"/></geometry>
    </collision>
  </link>
  <joint name="j_thigh_l" type="revolute"> <parent link="torso"/>
    <child link="thigh_l"/>
    <origin xyz="0.04 0 -0.2" rpy="0 0 0"/>
    <axis xyz="0 1 0"/>
    <limit lower="-1.57" upper="1.57" effort="100" velocity="10"/>
  </joint>

  <link name="shin_l">
    <inertial>
      <mass value="3"/>
      <origin xyz="0 0 -0.15" rpy="0 0 0"/> <inertia ixx="0.03" ixy="0" ixz="0" iyy="0.03" iyz="0" izz="0.005"/>
    </inertial>
    <visual>
      <origin xyz="0 0 -0.15" rpy="0 0 0"/>
      <geometry><box size="0.06 0.05 0.3"/></geometry>
      <material name="green"><color rgba="0 1 0 1"/></material>
    </visual>
    <collision>
      <origin xyz="0 0 -0.15" rpy="0 0 0"/>
      <geometry><box size="0.06 0.05 0.3"/></geometry>
    </collision>
  </link>
  <joint name="j_shin_l" type="revolute"> <parent link="thigh_l"/>
    <child link="shin_l"/>
    <origin xyz="0 0 -0.3" rpy="0 0 0"/> <axis xyz="0 1 0"/>
    <limit lower="0" upper="2.79" effort="100" velocity="10"/> </joint>

  <link name="foot_l">
     <inertial>
       <mass value="1"/>
       <origin xyz="0.04 0 -0.025" rpy="0 0 0"/> <inertia ixx="0.001" ixy="0" ixz="0" iyy="0.001" iyz="0" izz="0.001"/>
     </inertial>
    <visual>
       <origin xyz="0.04 0 -0.025" rpy="0 0 0"/>
      <geometry><box size="0.15 0.05 0.05"/></geometry>
      <material name="yellow"><color rgba="1 1 0 1"/></material>
    </visual>
    <collision>
       <origin xyz="0.04 0 -0.025" rpy="0 0 0"/>
      <geometry><box size="0.15 0.05 0.05"/></geometry>
    </collision>
  </link>
  <joint name="j_foot_l" type="revolute"> <parent link="shin_l"/>
    <child link="foot_l"/>
    <origin xyz="0 0 -0.3" rpy="0 0 0"/> <axis xyz="0 1 0"/>
    <limit lower="-0.785" upper="0.785" effort="50" velocity="10"/> </joint>

   <link name="thigh_r">
    <inertial>
      <mass value="5"/>
      <origin xyz="0 0 -0.15" rpy="0 0 0"/>
      <inertia ixx="0.05" ixy="0" ixz="0" iyy="0.05" iyz="0" izz="0.01"/>
    </inertial>
    <visual>
      <origin xyz="0 0 -0.15" rpy="0 0 0"/>
      <geometry><box size="0.08 0.05 0.3"/></geometry>
       <material name="red"/>
    </visual>
    <collision>
      <origin xyz="0 0 -0.15" rpy="0 0 0"/>
      <geometry><box size="0.08 0.05 0.3"/></geometry>
    </collision>
  </link>
  <joint name="j_thigh_r" type="revolute"> <parent link="torso"/>
    <child link="thigh_r"/>
    <origin xyz="-0.04 0 -0.2" rpy="0 0 0"/>
    <axis xyz="0 1 0"/>
    <limit lower="-1.57" upper="1.57" effort="100" velocity="10"/>
  </joint>

  <link name="shin_r">
     <inertial>
      <mass value="3"/>
      <origin xyz="0 0 -0.15" rpy="0 0 0"/>
      <inertia ixx="0.03" ixy="0" ixz="0" iyy="0.03" iyz="0" izz="0.005"/>
    </inertial>
    <visual>
      <origin xyz="0 0 -0.15" rpy="0 0 0"/>
      <geometry><box size="0.06 0.05 0.3"/></geometry>
      <material name="green"/>
    </visual>
    <collision>
      <origin xyz="0 0 -0.15" rpy="0 0 0"/>
      <geometry><box size="0.06 0.05 0.3"/></geometry>
    </collision>
  </link>
  <joint name="j_shin_r" type="revolute"> <parent link="thigh_r"/>
    <child link="shin_r"/>
    <origin xyz="0 0 -0.3" rpy="0 0 0"/>
    <axis xyz="0 1 0"/>
    <limit lower="0" upper="2.79" effort="100" velocity="10"/>
  </joint>

  <link name="foot_r">
     <inertial>
       <mass value="1"/>
       <origin xyz="0.04 0 -0.025" rpy="0 0 0"/>
       <inertia ixx="0.001" ixy="0" ixz="0" iyy="0.001" iyz="0" izz="0.001"/>
     </inertial>
    <visual>
       <origin xyz="0.04 0 -0.025" rpy="0 0 0"/>
      <geometry><box size="0.15 0.05 0.05"/></geometry>
      <material name="yellow"/>
    </visual>
    <collision>
       <origin xyz="0.04 0 -0.025" rpy="0 0 0"/>
      <geometry><box size="0.15 0.05 0.05"/></geometry>
    </collision>
  </link>
  <joint name="j_foot_r" type="revolute"> <parent link="shin_r"/>
    <child link="foot_r"/>
    <origin xyz="0 0 -0.3" rpy="0 0 0"/> <axis xyz="0 1 0"/>
     <limit lower="-0.785" upper="0.785" effort="50" velocity="10"/>
  </joint>

</robot>